Workbook

Sheet Index
A1: event_value | B1: schema_title | C1: api_version | D1: borana_schema_id | E1: mugie_schema | F1: icon_id | G1: image_url | H1: n_fields | I1: n_enums | J1: event_name | K1: event_category_display | L1: event_category_id | M1: event_updated_at | N1: sheet_name | O1: Open
A2: fatality | B2: EventType Test Data | C2: v1 | D2: =VLOOKUP(A2, borana_schemas!A:D, 4, FALSE) -> https://borana.pamdas.org/api/v1.0/activity/events/schema/eventtype/fatality | E2: =VLOOKUP(A2, mugie_schemas!A:D, 4, FALSE) -> #N/A | F2: human_activities_observation_rep | H2: 16 | I2: 5 | J2: Fatality | K2: Accident & Emergency | L2: fb9ee509-1dac-42ca-b0ec-7428d6a83214 | N2: fatality | O2: =HYPERLINK("#'fatality'!A1","Open") -> Open
A3: medical_evacuation_report | B3: EventType Test Data | C3: v1 | D3: =VLOOKUP(A3, borana_schemas!A:D, 4, FALSE) -> https://borana.pamdas.org/api/v1.0/activity/events/schema/eventtype/medical_evacuation_report | E3: =VLOOKUP(A3, mugie_schemas!A:D, 4, FALSE) -> #N/A | F3: medevac_rep | H3: 13 | I3: 3 | J3: Medical Evacuation | K3: Accident & Emergency | L3: fb9ee509-1dac-42ca-b0ec-7428d6a83214 | N3: medical_evacuation_report | O3: =HYPERLINK("#'medical_evacuation_report'!A1","Open") -> Open
A4: missing_persons | B4: EventType Test Data | C4: v1 | D4: =VLOOKUP(A4, borana_schemas!A:D, 4, FALSE) -> https://borana.pamdas.org/api/v1.0/activity/events/schema/eventtype/missing_persons | E4: =VLOOKUP(A4, mugie_schemas!A:D, 4, FALSE) -> #N/A | F4: missing_person_rep | H4: 19 | I4: 4 | J4: Missing Person(s) | K4: Accident & Emergency | L4: fb9ee509-1dac-42ca-b0ec-7428d6a83214 | N4: missing_persons | O4: =HYPERLINK("#'missing_persons'!A1","Open") -> Open
A5: mist_rep | B5: EventType Test Data | C5: v1 | D5: =VLOOKUP(A5, borana_schemas!A:D, 4, FALSE) -> https://borana.pamdas.org/api/v1.0/activity/events/schema/eventtype/mist_rep | E5: =VLOOKUP(A5, mugie_schemas!A:D, 4, FALSE) -> #N/A | F5: mist_rep | H5: 12 | I5: 3 | J5: ATMIST | K5: Accident & Emergency | L5: fb9ee509-1dac-42ca-b0ec-7428d6a83214 | N5: mist_rep | O5: =HYPERLINK("#'mist_rep'!A1","Open") -> Open
A6: vehicle_accident_rep | B6: EventType Test Data | C6: v1 | D6: =VLOOKUP(A6, borana_schemas!A:D, 4, FALSE) -> https://borana.pamdas.org/api/v1.0/activity/events/schema/eventtype/vehicle_accident_rep | E6: =VLOOKUP(A6, mugie_schemas!A:D, 4, FALSE) -> #N/A | F6: accident_rep | H6: 21 | I6: 5 | J6: Vehicle Accident | K6: Accident & Emergency | L6: fb9ee509-1dac-42ca-b0ec-7428d6a83214 | N6: vehicle_accident_rep | O6: =HYPERLINK("#'vehicle_accident_rep'!A1","Open") -> Open
A7: wild_fire | B7: Wild Fire Report | C7: v1 | D7: =VLOOKUP(A7, borana_schemas!A:D, 4, FALSE) -> https://borana.pamdas.org/api/v1.0/activity/events/schema/eventtype/wild_fire | E7: =VLOOKUP(A7, mugie_schemas!A:D, 4, FALSE) -> #N/A | F7: fire_rep | H7: 12 | I7: 6 | J7: Wild Fire | K7: Accident & Emergency | N7: wild_fire | O7: =HYPERLINK("#'wild_fire'!A1","Open") -> Open
A8: atmist_backup | B8: ATMIST | C8: v1 | D8: =VLOOKUP(A8, borana_schemas!A:D, 4, FALSE) -> https://borana.pamdas.org/api/v1.0/activity/events/schema/eventtype/atmist_backup | E8: =VLOOKUP(A8, mugie_schemas!A:D, 4, FALSE) -> #N/A | F8: mist_rep | H8: 13 | I8: 2 | J8: ATMIST | K8: Accident & Emergency OpsRoom | L8: 781bea94-4fdc-450d-8283-cbf77dfe3763 | N8: atmist_backup | O8: =HYPERLINK("#'atmist_backup'!A1","Open") -> Open
A9: fatality_backup | B9: EventType Test Data | C9: v1 | D9: =VLOOKUP(A9, borana_schemas!A:D, 4, FALSE) -> https://borana.pamdas.org/api/v1.0/activity/events/schema/eventtype/fatality_backup | E9: =VLOOKUP(A9, mugie_schemas!A:D, 4, FALSE) -> #N/A | F9: human_activities_observation_rep | H9: 17 | I9: 4 | J9: Fatality | K9: Accident & Emergency OpsRoom | L9: 781bea94-4fdc-450d-8283-cbf77dfe3763 | N9: fatality_backup | O9: =HYPERLINK("#'fatality_backup'!A1","Open") -> Open
A10: med_evac_backup | B10: EventType Test Data | C10: v1 | D10: =VLOOKUP(A10, borana_schemas!A:D, 4, FALSE) -> https://borana.pamdas.org/api/v1.0/activity/events/schema/eventtype/med_evac_backup | E10: =VLOOKUP(A10, mugie_schemas!A:D, 4, FALSE) -> #N/A | F10: medevac_request_rep | H10: 14 | I10: 2 | J10: Medical Evacuation | K10: Accident & Emergency OpsRoom | L10: 781bea94-4fdc-450d-8283-cbf77dfe3763 | N10: med_evac_backup | O10: =HYPERLINK("#'med_evac_backup'!A1","Open") -> Open
A11: missing_person_backup | B11: EventType Test Data | C11: v1 | D11: =VLOOKUP(A11, borana_schemas!A:D, 4, FALSE) -> https://borana.pamdas.org/api/v1.0/activity/events/schema/eventtype/missing_person_backup | E11: =VLOOKUP(A11, mugie_schemas!A:D, 4, FALSE) -> #N/A | F11: missing_person_rep | H11: 20 | I11: 3 | J11: Missing Person(s) | K11: Accident & Emergency OpsRoom | L11: 781bea94-4fdc-450d-8283-cbf77dfe3763 | N11: missing_person_backup | O11: =HYPERLINK("#'missing_person_backup'!A1","Open") -> Open
A12: veh_acc_backup | B12: EventType Test Data | C12: v1 | D12: =VLOOKUP(A12, borana_schemas!A:D, 4, FALSE) -> https://borana.pamdas.org/api/v1.0/activity/events/schema/eventtype/veh_acc_backup | E12: =VLOOKUP(A12, mugie_schemas!A:D, 4, FALSE) -> #N/A | F12: accident_rep | H12: 22 | I12: 4 | J12: Vehicle Accident | K12: Accident & Emergency OpsRoom | L12: 781bea94-4fdc-450d-8283-cbf77dfe3763 | N12: veh_acc_backup | O12: =HYPERLINK("#'veh_acc_backup'!A1","Open") -> Open
A13: wildfire_backup | B13: Wild Fire Report | C13: v1 | D13: =VLOOKUP(A13, borana_schemas!A:D, 4, FALSE) -> https://borana.pamdas.org/api/v1.0/activity/events/schema/eventtype/wildfire_backup | E13: =VLOOKUP(A13, mugie_schemas!A:D, 4, FALSE) -> #N/A | F13: fire_rep | H13: 13 | I13: 5 | J13: Wild Fire | K13: Accident & Emergency OpsRoom | N13: wildfire_backup | O13: =HYPERLINK("#'wildfire_backup'!A1","Open") -> Open
A14: air_ops_boma_sighting | B14: Boma Sighting | C14: v1 | D14: =VLOOKUP(A14, borana_schemas!A:D, 4, FALSE) -> https://borana.pamdas.org/api/v1.0/activity/events/schema/eventtype/air_ops_boma_sighting | E14: =VLOOKUP(A14, mugie_schemas!A:D, 4, FALSE) -> #N/A | F14: boma_rep | H14: 8 | I14: 2 | J14: Boma Sighting | K14: Air Ops | N14: air_ops_boma_sighting | O14: =HYPERLINK("#'air_ops_boma_sighting'!A1","Open") -> Open
A15: air_ops_camel_sighting | B15: Camel Sighting | C15: v1 | D15: =VLOOKUP(A15, borana_schemas!A:D, 4, FALSE) -> https://borana.pamdas.org/api/v1.0/activity/events/schema/eventtype/air_ops_camel_sighting | E15: =VLOOKUP(A15, mugie_schemas!A:D, 4, FALSE) -> #N/A | F15: air_ops_camel_sighting | H15: 3 | I15: 0 | J15: Camel Sighting | K15: Air Ops | N15: air_ops_camel_sighting | O15: =HYPERLINK("#'air_ops_camel_sighting'!A1","Open") -> Open
A16: air_ops_cattle_sighting | B16: Cattle Sighting | C16: v1 | D16: =VLOOKUP(A16, borana_schemas!A:D, 4, FALSE) -> https://borana.pamdas.org/api/v1.0/activity/events/schema/eventtype/air_ops_cattle_sighting | E16: =VLOOKUP(A16, mugie_schemas!A:D, 4, FALSE) -> #N/A | F16: bull_rep | H16: 3 | I16: 0 | J16: Cattle Sighting | K16: Air Ops | N16: air_ops_cattle_sighting | O16: =HYPERLINK("#'air_ops_cattle_sighting'!A1","Open") -> Open
A17: air_ops_elephant_carcass | B17: Elephant Carcass | C17: v1 | D17: =VLOOKUP(A17, borana_schemas!A:D, 4, FALSE) -> https://borana.pamdas.org/api/v1.0/activity/events/schema/eventtype/air_ops_elephant_carcass | E17: =VLOOKUP(A17, mugie_schemas!A:D, 4, FALSE) -> #N/A | F17: elephant_mortality_rep | H17: 4 | I17: 2 | J17: Elephant Carcass | K17: Air Ops | N17: air_ops_elephant_carcass | O17: =HYPERLINK("#'air_ops_elephant_carcass'!A1","Open") -> Open
A18: air_ops_logging | B18: Logging | C18: v1 | D18: =VLOOKUP(A18, borana_schemas!A:D, 4, FALSE) -> https://borana.pamdas.org/api/v1.0/activity/events/schema/eventtype/air_ops_logging | E18: =VLOOKUP(A18, mugie_schemas!A:D, 4, FALSE) -> #N/A | F18: deforestation_rep | H18: 6 | I18: 3 | J18: Logging | K18: Air Ops | N18: air_ops_logging | O18: =HYPERLINK("#'air_ops_logging'!A1","Open") -> Open
A19: air_ops_people_sighting | B19: People Sighting | C19: v1 | D19: =VLOOKUP(A19, borana_schemas!A:D, 4, FALSE) -> https://borana.pamdas.org/api/v1.0/activity/events/schema/eventtype/air_ops_people_sighting | E19: =VLOOKUP(A19, mugie_schemas!A:D, 4, FALSE) -> #N/A | F19: suspicious_person_rep | H19: 5 | I19: 2 | J19: People Sighting | K19: Air Ops | N19: air_ops_people_sighting | O19: =HYPERLINK("#'air_ops_people_sighting'!A1","Open") -> Open
A20: air_ops_shoat_sighting | B20: Shoats Sighting | C20: v1 | D20: =VLOOKUP(A20, borana_schemas!A:D, 4, FALSE) -> https://borana.pamdas.org/api/v1.0/activity/events/schema/eventtype/air_ops_shoat_sighting | E20: =VLOOKUP(A20, mugie_schemas!A:D, 4, FALSE) -> #N/A | F20: goat_rep | H20: 3 | I20: 0 | J20: Shoat Sighting | K20: Air Ops | N20: air_ops_shoat_sighting | O20: =HYPERLINK("#'air_ops_shoat_sighting'!A1","Open") -> Open
A21: air_ops_wildlife_carcass | B21: Wildlife Carcass | C21: v1 | D21: =VLOOKUP(A21, borana_schemas!A:D, 4, FALSE) -> https://borana.pamdas.org/api/v1.0/activity/events/schema/eventtype/air_ops_wildlife_carcass | E21: =VLOOKUP(A21, mugie_schemas!A:D, 4, FALSE) -> #N/A | F21: carcass_rep | H21: 5 | I21: 2 | J21: Wildlife Carcass | K21: Air Ops | N21: air_ops_wildlife_carcass | O21: =HYPERLINK("#'air_ops_wildlife_carcass'!A1","Open") -> Open
A22: air_ops_wildlife_sighting | B22: Other Wildlife Sighting | C22: v1 | D22: =VLOOKUP(A22, borana_schemas!A:D, 4, FALSE) -> https://borana.pamdas.org/api/v1.0/activity/events/schema/eventtype/air_ops_wildlife_sighting | E22: =VLOOKUP(A22, mugie_schemas!A:D, 4, FALSE) -> #N/A | F22: other_wildlife_sightings_rep | H22: 2 | I22: 1 | J22: Wildlife Sighting | K22: Air Ops | N22: air_ops_wildlife_sighting | O22: =HYPERLINK("#'air_ops_wildlife_sighting'!A1","Open") -> Open
A23: charcoal_kiln | B23: Charcoal Kiln | C23: v1 | D23: =VLOOKUP(A23, borana_schemas!A:D, 4, FALSE) -> https://borana.pamdas.org/api/v1.0/activity/events/schema/eventtype/charcoal_kiln | E23: =VLOOKUP(A23, mugie_schemas!A:D, 4, FALSE) -> #N/A | F23: charcoal_kiln_rep | H23: 4 | I23: 1 | J23: Charcoal Kiln | K23: Air Ops | N23: charcoal_kiln | O23: =HYPERLINK("#'charcoal_kiln'!A1","Open") -> Open
A24: degraded_area | B24: Erosion Report Report | C24: v1 | D24: =VLOOKUP(A24, borana_schemas!A:D, 4, FALSE) -> https://borana.pamdas.org/api/v1.0/activity/events/schema/eventtype/degraded_area | E24: =VLOOKUP(A24, mugie_schemas!A:D, 4, FALSE) -> #N/A | F24: spur-trail_rep | H24: 10 | I24: 4 | J24: Degraded Area | K24: Air Ops | N24: degraded_area | O24: =HYPERLINK("#'degraded_area'!A1","Open") -> Open
A25: nesting_site | B25: EventType Test Data | C25: v1 | E25: =VLOOKUP(A25, mugie_schemas!A:D, 4, FALSE) -> https://mugie.pamdas.org/api/v1.0/activity/events/schema/eventtype/nesting_site | F25: nest_rep | G25: https://mugie.pamdas.org/static/sprite-src/nest_rep.svg | H25: 5 | I25: 1 | J25: Nesting Site | K25: Avian Events | L25: 87b9675f-312c-4985-a5bf-38ff4423146e | N25: nesting_site | O25: =HYPERLINK("#'nesting_site'!A1","Open") -> Open
A26: raptor_sighting | B26: EventType Test Data | C26: v1 | E26: =VLOOKUP(A26, mugie_schemas!A:D, 4, FALSE) -> https://mugie.pamdas.org/api/v1.0/activity/events/schema/eventtype/raptor_sighting | F26: hawk_rep | G26: https://mugie.pamdas.org/static/sprite-src/hawk_rep.svg | H26: 9 | I26: 4 | J26: Raptor Sighting | K26: Avian Events | L26: 87b9675f-312c-4985-a5bf-38ff4423146e | N26: raptor_sighting | O26: =HYPERLINK("#'raptor_sighting'!A1","Open") -> Open
A27: disease_rep | B27: Disease Monitoring Report | C27: v1 | D27: =VLOOKUP(A27, borana_schemas!A:D, 4, FALSE) -> https://borana.pamdas.org/api/v1.0/activity/events/schema/eventtype/disease_rep | E27: =VLOOKUP(A27, mugie_schemas!A:D, 4, FALSE) -> #N/A | F27: disease_rep | H27: 13 | I27: 9 | J27: Disease Monitoring | K27: Bio And Eco Monitoring | N27: disease_rep | O27: =HYPERLINK("#'disease_rep'!A1","Open") -> Open
A28: elephant_incident_vrf | B28: Rangelands Report (rangelands_rep) | C28: v1 | D28: =VLOOKUP(A28, borana_schemas!A:D, 4, FALSE) -> https://borana.pamdas.org/api/v1.0/activity/events/schema/eventtype/elephant_incident_vrf | E28: =VLOOKUP(A28, mugie_schemas!A:D, 4, FALSE) -> #N/A | F28: animalfence_rep | H28: 12 | I28: 6 | J28: Elephant Incident Verification | K28: Bio And Eco Monitoring | N28: elephant_incident_vrf | O28: =HYPERLINK("#'elephant_incident_vrf'!A1","Open") -> Open
A29: elephant_mortality | B29: Elephant Mortality | C29: v1 | D29: =VLOOKUP(A29, borana_schemas!A:D, 4, FALSE) -> https://borana.pamdas.org/api/v1.0/activity/events/schema/eventtype/elephant_mortality | E29: =VLOOKUP(A29, mugie_schemas!A:D, 4, FALSE) -> #N/A | F29: elephant_mortality | H29: 28 | I29: 15 | J29: Elephant Mortality | K29: Bio And Eco Monitoring | L29: 03cc816c-724a-4365-8eb7-3a09843ff196 | N29: elephant_mortality | O29: =HYPERLINK("#'elephant_mortality'!A1","Open") -> Open
A30: eov_monitoring | B30: EOV Monitoring | C30: v1 | D30: =VLOOKUP(A30, borana_schemas!A:D, 4, FALSE) -> https://borana.pamdas.org/api/v1.0/activity/events/schema/eventtype/eov_monitoring | E30: =VLOOKUP(A30, mugie_schemas!A:D, 4, FALSE) -> #N/A | F30: corridor_clearance_rep | H30: 24 | I30: 19 | J30: EOV | K30: Bio And Eco Monitoring | L30: 03cc816c-724a-4365-8eb7-3a09843ff196 | N30: eov_monitoring | O30: =HYPERLINK("#'eov_monitoring'!A1","Open") -> Open
A31: injured_abandoned_rep | B31: Injured Abandoned Animal Report | C31: v1 | D31: =VLOOKUP(A31, borana_schemas!A:D, 4, FALSE) -> https://borana.pamdas.org/api/v1.0/activity/events/schema/eventtype/injured_abandoned_rep | E31: =VLOOKUP(A31, mugie_schemas!A:D, 4, FALSE) -> #N/A | F31: mist_rep | H31: 13 | I31: 6 | J31: Injured/Abandoned Animal | K31: Bio And Eco Monitoring | N31: injured_abandoned_rep | O31: =HYPERLINK("#'injured_abandoned_rep'!A1","Open") -> Open
A32: invasive_rep | B32: Invasive Alien Plants Report | C32: v1 | D32: =VLOOKUP(A32, borana_schemas!A:D, 4, FALSE) -> https://borana.pamdas.org/api/v1.0/activity/events/schema/eventtype/invasive_rep | E32: https://mugie.pamdas.org/api/v1.0/activity/events/schema/eventtype/invasive_species_rep | F32: invasive_species_rep | H32: 17 | I32: 10 | J32: Invasive Alien Plant Species | K32: Bio And Eco Monitoring | N32: invasive_rep | O32: =HYPERLINK("#'invasive_rep'!A1","Open") -> Open
A33: lewa_postmortem_rep | B33: Post Mortem Report | C33: v1 | D33: =VLOOKUP(A33, borana_schemas!A:D, 4, FALSE) -> https://borana.pamdas.org/api/v1.0/activity/events/schema/eventtype/lewa_postmortem_rep | E33: =VLOOKUP(A33, mugie_schemas!A:D, 4, FALSE) -> #N/A | F33: lewa_postmortem_rep | H33: 13 | I33: 4 | J33: Post Mortem | K33: Bio And Eco Monitoring | N33: lewa_postmortem_rep | O33: =HYPERLINK("#'lewa_postmortem_rep'!A1","Open") -> Open
A34: lion_sighting | B34: EventType Test Data | C34: v1 | D34: =VLOOKUP(A34, borana_schemas!A:D, 4, FALSE) -> https://borana.pamdas.org/api/v1.0/activity/events/schema/eventtype/lion_sighting | E34: =VLOOKUP(A34, mugie_schemas!A:D, 4, FALSE) -> https://mugie.pamdas.org/api/v1.0/activity/events/schema/eventtype/lion_sighting | F34: lion_sighting_rep | H34: 21 | I34: 15 | J34: Lion Sighting | K34: Bio And Eco Monitoring | L34: 03cc816c-724a-4365-8eb7-3a09843ff196 | N34: lion_sighting | O34: =HYPERLINK("#'lion_sighting'!A1","Open") -> Open
A35: mgt_burn_rep | B35: Controlled Burn Report | C35: v1 | D35: =VLOOKUP(A35, borana_schemas!A:D, 4, FALSE) -> https://borana.pamdas.org/api/v1.0/activity/events/schema/eventtype/mgt_burn_rep | E35: =VLOOKUP(A35, mugie_schemas!A:D, 4, FALSE) -> #N/A | F35: burn_rep | H35: 15 | I35: 7 | J35: Controlled Burn | K35: Bio And Eco Monitoring | N35: mgt_burn_rep | O35: =HYPERLINK("#'mgt_burn_rep'!A1","Open") -> Open
A36: rainfall_rep | B36: Rainfall Report Report | C36: v1 | D36: =VLOOKUP(A36, borana_schemas!A:D, 4, FALSE) -> https://borana.pamdas.org/api/v1.0/activity/events/schema/eventtype/rainfall_rep | E36: =VLOOKUP(A36, mugie_schemas!A:D, 4, FALSE) -> #N/A | F36: rainfall_rep | H36: 4 | I36: 2 | J36: Rainfall Report | K36: Bio And Eco Monitoring | N36: rainfall_rep | O36: =HYPERLINK("#'rainfall_rep'!A1","Open") -> Open
A37: resource_use | B37: Resource Use Report | C37: v1 | D37: =VLOOKUP(A37, borana_schemas!A:D, 4, FALSE) -> https://borana.pamdas.org/api/v1.0/activity/events/schema/eventtype/resource_use | E37: =VLOOKUP(A37, mugie_schemas!A:D, 4, FALSE) -> #N/A | F37: resource_use | H37: 7 | I37: 5 | J37: Resource Use | K37: Bio And Eco Monitoring | N37: resource_use | O37: =HYPERLINK("#'resource_use'!A1","Open") -> Open
A38: soil_mentor_basic | B38: Soil Mentor Report | C38: v1 | D38: =VLOOKUP(A38, borana_schemas!A:D, 4, FALSE) -> https://borana.pamdas.org/api/v1.0/activity/events/schema/eventtype/soil_mentor_basic | E38: =VLOOKUP(A38, mugie_schemas!A:D, 4, FALSE) -> #N/A | F38: vulva_inspection_rep | H38: 37 | I38: 11 | J38: Soil Mentor Basic | K38: Bio And Eco Monitoring | N38: soil_mentor_basic | O38: =HYPERLINK("#'soil_mentor_basic'!A1","Open") -> Open
A39: soil_qual_test | B39: Soil Quality Test | C39: v1 | D39: =VLOOKUP(A39, borana_schemas!A:D, 4, FALSE) -> https://borana.pamdas.org/api/v1.0/activity/events/schema/eventtype/soil_qual_test | E39: =VLOOKUP(A39, mugie_schemas!A:D, 4, FALSE) -> #N/A | F39: generic_rep | H39: 16 | I39: 3 | J39: Soil Quality Test | K39: Bio And Eco Monitoring | N39: soil_qual_test | O39: =HYPERLINK("#'soil_qual_test'!A1","Open") -> Open
A40: wildlife_mortality | B40: EventType Test Data | C40: v1 | D40: =VLOOKUP(A40, borana_schemas!A:D, 4, FALSE) -> https://borana.pamdas.org/api/v1.0/activity/events/schema/eventtype/wildlife_mortality | E40: =VLOOKUP(A40, mugie_schemas!A:D, 4, FALSE) -> #N/A | F40: carcass_rep | H40: 13 | I40: 6 | J40: Wildlife Mortality | K40: Bio And Eco Monitoring | L40: 03cc816c-724a-4365-8eb7-3a09843ff196 | N40: wildlife_mortality | O40: =HYPERLINK("#'wildlife_mortality'!A1","Open") -> Open
...

Sheet borana_schemas
A1: event_value | B1: schema_title | C1: api_version | D1: schema_id | E1: icon_id | F1: image_url
A2: aip_polygon | B2: Invasive Alien Plants Report | C2: v1 | D2: https://borana.pamdas.org/api/v1.0/activity/events/schema/eventtype/aip_polygon | E2: invasive_species_rep | F2: https://borana.pamdas.org/static/invasive_species-black.svg
A3: aip_tourism | B3: Invasive Alien Plants Report | C3: v1 | D3: https://borana.pamdas.org/api/v1.0/activity/events/schema/eventtype/aip_tourism | E3: invasive_species_rep | F3: https://borana.pamdas.org/static/invasive_species-black.svg
A4: air_ops_boma_sighting | B4: Boma Sighting | C4: v1 | D4: https://borana.pamdas.org/api/v1.0/activity/events/schema/eventtype/air_ops_boma_sighting | E4: boma_rep | F4: https://borana.pamdas.org/static/sprite-src/boma_rep.svg
A5: air_ops_camel_sighting | B5: Camel Sighting | C5: v1 | D5: https://borana.pamdas.org/api/v1.0/activity/events/schema/eventtype/air_ops_camel_sighting | E5: air_ops_camel_sighting | F5: https://borana.pamdas.org/static/generic-black.svg
A6: air_ops_cattle_sighting | B6: Cattle Sighting | C6: v1 | D6: https://borana.pamdas.org/api/v1.0/activity/events/schema/eventtype/air_ops_cattle_sighting | E6: bull_rep | F6: https://borana.pamdas.org/static/sprite-src/bull_rep.svg
A7: air_ops_elephant_carcass | B7: Elephant Carcass | C7: v1 | D7: https://borana.pamdas.org/api/v1.0/activity/events/schema/eventtype/air_ops_elephant_carcass | E7: elephant_mortality_rep | F7: https://borana.pamdas.org/static/elephant_mortality-black.svg
A8: air_ops_logging | B8: Logging | C8: v1 | D8: https://borana.pamdas.org/api/v1.0/activity/events/schema/eventtype/air_ops_logging | E8: deforestation_rep | F8: https://borana.pamdas.org/static/sprite-src/deforestation_rep.svg
A9: air_ops_people_sighting | B9: People Sighting | C9: v1 | D9: https://borana.pamdas.org/api/v1.0/activity/events/schema/eventtype/air_ops_people_sighting | E9: suspicious_person_rep | F9: https://borana.pamdas.org/static/suspicious_person_rep-black.svg
A10: air_ops_shoat_sighting | B10: Shoats Sighting | C10: v1 | D10: https://borana.pamdas.org/api/v1.0/activity/events/schema/eventtype/air_ops_shoat_sighting | E10: goat_rep | F10: https://borana.pamdas.org/static/sprite-src/goat_rep.svg
A11: air_ops_wildlife_carcass | B11: Wildlife Carcass | C11: v1 | D11: https://borana.pamdas.org/api/v1.0/activity/events/schema/eventtype/air_ops_wildlife_carcass | E11: carcass_rep | F11: https://borana.pamdas.org/static/carcass-black.svg
A12: air_ops_wildlife_sighting | B12: Other Wildlife Sighting | C12: v1 | D12: https://borana.pamdas.org/api/v1.0/activity/events/schema/eventtype/air_ops_wildlife_sighting | E12: other_wildlife_sightings_rep | F12: https://borana.pamdas.org/static/other_wildlife_sightings-black.svg
... A132: wr_removal | B132: EventType Test Data | C132: v1 | D132: https://borana.pamdas.org/api/v1.0/activity/events/schema/eventtype/wr_removal | E132: rhino_territorial_movement_rep | F132: https://borana.pamdas.org/static/rhino_territorial_movement-black.svg

Sheet mugie_schemas
A1: event_value | B1: schema_title | C1: api_version | D1: schema_id | E1: icon_id | F1: image_url | G1: n_fields | H1: n_enums | I1: event_name | J1: event_category_display | K1: event_category_id | L1: event_is_active | M1: event_updated_at | N1: sheet_name | O1: Open
A2: acoustic_detection | B2: Acoustic Detection (acoustic_detection) | C2: v1 | D2: https://mugie.pamdas.org/api/v1.0/activity/events/schema/eventtype/acoustic_detection | E2: radar_rep | F2: https://mugie.pamdas.org/static/sprite-src/radar_rep.svg | G2: 3 | H2: 0 | I2: Acoustic Detection | J2: Analyzer Event | K2: ef230385-5afc-40d1-ad07-c811f6da2b3c | L2: TRUE | N2: acoustic_detection | O2: =HYPERLINK("#'acoustic_detection'!A1","Open") -> Open
A3: firms_rep | B3: FIRMS Fire Report Schema | C3: v1 | D3: https://mugie.pamdas.org/api/v1.0/activity/events/schema/eventtype/firms_rep | E3: firms_rep | F3: https://mugie.pamdas.org/static/firms_rep-black.svg | G3: 6 | H3: 0 | I3: FIRMS Report | J3: Analyzer Event | K3: ef230385-5afc-40d1-ad07-c811f6da2b3c | L3: TRUE | N3: firms_rep | O3: =HYPERLINK("#'firms_rep'!A1","Open") -> Open
A4: gfw_activefire_alert | B4: Event Type Global Forest Watch Active Fire Alert | C4: v1 | D4: https://mugie.pamdas.org/api/v1.0/activity/events/schema/eventtype/gfw_activefire_alert | E4: fire_rep | F4: https://mugie.pamdas.org/static/fire-black.svg | G4: 9 | H4: 0 | I4: Active Fire Alert (GFW) | J4: Analyzer Event | K4: ef230385-5afc-40d1-ad07-c811f6da2b3c | L4: TRUE | N4: gfw_activefire_alert | O4: =HYPERLINK("#'gfw_activefire_alert'!A1","Open") -> Open
A5: gfw_glad_alert | B5: Event Type Global Forest Watch Tree Loss Alert | C5: v1 | D5: https://mugie.pamdas.org/api/v1.0/activity/events/schema/eventtype/gfw_glad_alert | E5: deforestation_rep | F5: https://mugie.pamdas.org/static/sprite-src/deforestation_rep.svg | G5: 4 | H5: 0 | I5: GLAD Tree-Loss Alert (GFW) | J5: Analyzer Event | K5: ef230385-5afc-40d1-ad07-c811f6da2b3c | L5: TRUE | N5: gfw_glad_alert | O5: =HYPERLINK("#'gfw_glad_alert'!A1","Open") -> Open
A6: immobility | B6: EventType Immobility | C6: v1 | D6: https://mugie.pamdas.org/api/v1.0/activity/events/schema/eventtype/immobility | E6: immobility | F6: https://mugie.pamdas.org/static/immobility-black.svg | G6: 7 | H6: 0 | I6: Immobility | J6: Analyzer Event | K6: ef230385-5afc-40d1-ad07-c811f6da2b3c | L6: TRUE | N6: immobility | O6: =HYPERLINK("#'immobility'!A1","Open") -> Open
A7: immobility_all_clear | B7: EventType Immobility | C7: v1 | D7: https://mugie.pamdas.org/api/v1.0/activity/events/schema/eventtype/immobility_all_clear | E7: immobility_all_clear | F7: https://mugie.pamdas.org/static/immobility_all_clear-black.svg | G7: 7 | H7: 0 | I7: Immobility All Clear | J7: Analyzer Event | K7: ef230385-5afc-40d1-ad07-c811f6da2b3c | L7: TRUE | N7: immobility_all_clear | O7: =HYPERLINK("#'immobility_all_clear'!A1","Open") -> Open
A8: low_speed_percentile | B8: EventType Low Speed Percentile | C8: v1 | D8: https://mugie.pamdas.org/api/v1.0/activity/events/schema/eventtype/low_speed_percentile | E8: low_speed_percentile | F8: https://mugie.pamdas.org/static/low_speed_percentile-black.svg | G8: 6 | H8: 0 | I8: Low Speed (Percentile) | J8: Analyzer Event | K8: ef230385-5afc-40d1-ad07-c811f6da2b3c | L8: TRUE | N8: low_speed_percentile | O8: =HYPERLINK("#'low_speed_percentile'!A1","Open") -> Open
A9: low_speed_wilcoxon | B9: EventType Low Speed Wilcox | C9: v1 | D9: https://mugie.pamdas.org/api/v1.0/activity/events/schema/eventtype/low_speed_wilcoxon | E9: low_speed_wilcoxon | F9: https://mugie.pamdas.org/static/low_speed_wilcoxon-black.svg | G9: 4 | H9: 0 | I9: Low Speed (Wilcoxon) | J9: Analyzer Event | K9: ef230385-5afc-40d1-ad07-c811f6da2b3c | L9: TRUE | N9: low_speed_wilcoxon | O9: =HYPERLINK("#'low_speed_wilcoxon'!A1","Open") -> Open
A10: low_speed_wilcoxon_all_clear | B10: EventType Low Speed Wilcox All Clear | C10: v1 | D10: https://mugie.pamdas.org/api/v1.0/activity/events/schema/eventtype/low_speed_wilcoxon_all_clear | E10: low_speed_wilcoxon_all_clear | F10: https://mugie.pamdas.org/static/generic-black.svg | G10: 5 | H10: 0 | I10: Low Speed (Wilcoxon) All Clear | J10: Analyzer Event | K10: ef230385-5afc-40d1-ad07-c811f6da2b3c | L10: TRUE | N10: low_speed_wilcoxon_all_clear | O10: =HYPERLINK("#'low_speed_wilcoxon_all_clear'!A1","Open") -> Open
A11: proximity | B11: EventType Proximity | C11: v1 | D11: https://mugie.pamdas.org/api/v1.0/activity/events/schema/eventtype/proximity | E11: proximity | F11: https://mugie.pamdas.org/static/sprite-src/proximity.svg | G11: 7 | H11: 0 | I11: Proximity | J11: Analyzer Event | K11: ef230385-5afc-40d1-ad07-c811f6da2b3c | L11: TRUE | N11: proximity | O11: =HYPERLINK("#'proximity'!A1","Open") -> Open
A12: silence_source_provider_rep | B12: Entry Alert | C12: v1 | D12: https://mugie.pamdas.org/api/v1.0/activity/events/schema/eventtype/silence_source_provider_rep | E12: silence_source_provider_rep | F12: https://mugie.pamdas.org/static/sprite-src/silence_source_provider_rep.svg | G12: 3 | H12: 0 | I12: Silent Source Provider | J12: Analyzer Event | K12: ef230385-5afc-40d1-ad07-c811f6da2b3c | L12: TRUE | N12: silence_source_provider_rep | O12: =HYPERLINK("#'silence_source_provider_rep'!A1","Open") -> Open
A13: silence_source_rep | B13: Entry Alert | C13: v1 | D13: https://mugie.pamdas.org/api/v1.0/activity/events/schema/eventtype/silence_source_rep | E13: silence_source_rep | F13: https://mugie.pamdas.org/static/sprite-src/silence_source_rep.svg | G13: 7 | H13: 0 | I13: Silent Source | J13: Analyzer Event | K13: ef230385-5afc-40d1-ad07-c811f6da2b3c | L13: TRUE | N13: silence_source_rep | O13: =HYPERLINK("#'silence_source_rep'!A1","Open") -> Open
A14: subject_proximity | B14: Subject Proximity Schema | C14: v1 | D14: https://mugie.pamdas.org/api/v1.0/activity/events/schema/eventtype/subject_proximity | E14: subject_proximity | F14: https://mugie.pamdas.org/static/sprite-src/subject_proximity.svg | G14: 10 | H14: 0 | I14: Subject Proximity | J14: Analyzer Event | K14: ef230385-5afc-40d1-ad07-c811f6da2b3c | L14: TRUE | N14: subject_proximity | O14: =HYPERLINK("#'subject_proximity'!A1","Open") -> Open
A15: nesting_site | B15: EventType Test Data | C15: v1 | D15: https://mugie.pamdas.org/api/v1.0/activity/events/schema/eventtype/nesting_site | E15: nest_rep | F15: https://mugie.pamdas.org/static/sprite-src/nest_rep.svg | G15: 5 | H15: 1 | I15: Nesting Site | J15: Avian Events | K15: 87b9675f-312c-4985-a5bf-38ff4423146e | L15: TRUE | N15: nesting_site | O15: =HYPERLINK("#'nesting_site'!A1","Open") -> Open
A16: raptor_sighting | B16: EventType Test Data | C16: v1 | D16: https://mugie.pamdas.org/api/v1.0/activity/events/schema/eventtype/raptor_sighting | E16: hawk_rep | F16: https://mugie.pamdas.org/static/sprite-src/hawk_rep.svg | G16: 9 | H16: 4 | I16: Raptor Sighting | J16: Avian Events | K16: 87b9675f-312c-4985-a5bf-38ff4423146e | L16: TRUE | N16: raptor_sighting | O16: =HYPERLINK("#'raptor_sighting'!A1","Open") -> Open
A17: invasive_species_rep | B17: Invasive Species (invasive_species_rep) | C17: v1 | D17: https://mugie.pamdas.org/api/v1.0/activity/events/schema/eventtype/invasive_species_rep | E17: invasive_species_rep | F17: https://mugie.pamdas.org/static/invasive_species-black.svg | G17: 3 | H17: 3 | I17: Invasive Species | J17: HIDDEN | K17: 50acb72c-5038-4f7f-9cb6-d432026f5032 | L17: TRUE | N17: invasive_species_rep | O17: =HYPERLINK("#'invasive_species_rep'!A1","Open") -> Open
A18: airplane | B18: Trespassing Report | C18: v1 | D18: https://mugie.pamdas.org/api/v1.0/activity/events/schema/eventtype/airplane | E18: plane-patrol-icon | F18: https://mugie.pamdas.org/static/sprite-src/plane-patrol-icon.svg | G18: 5 | H18: 2 | I18: Airplane | J18: Human Activities | K18: 748f7f8a-1a22-4300-9229-b7e15e7ec142 | L18: TRUE | N18: airplane | O18: =HYPERLINK("#'airplane'!A1","Open") -> Open
A19: armed_people | B19: Gunshot Report | C19: v1 | D19: https://mugie.pamdas.org/api/v1.0/activity/events/schema/eventtype/armed_people | E19: bushmeat_poacher_rep | F19: https://mugie.pamdas.org/static/sprite-src/bushmeat_poacher_rep.svg | G19: 3 | H19: 0 | I19: Armed people | J19: Human Activities | K19: 748f7f8a-1a22-4300-9229-b7e15e7ec142 | L19: TRUE | N19: armed_people | O19: =HYPERLINK("#'armed_people'!A1","Open") -> Open
A20: bushmeattrading | B20: Bushmeat & Trading Report | C20: v1 | D20: https://mugie.pamdas.org/api/v1.0/activity/events/schema/eventtype/bushmeattrading | E20: bushmeat_poacher_rep | F20: https://mugie.pamdas.org/static/sprite-src/bushmeat_poacher_rep.svg | G20: 8 | H20: 3 | I20: Bushmeat & Trophy | J20: Human Activities | K20: 748f7f8a-1a22-4300-9229-b7e15e7ec142 | L20: TRUE | N20: bushmeattrading | O20: =HYPERLINK("#'bushmeattrading'!A1","Open") -> Open
A21: fence_rp | B21: EventType fence Data | C21: v1 | D21: https://mugie.pamdas.org/api/v1.0/activity/events/schema/eventtype/fence_rp | E21: fence_voltage_rep | F21: https://mugie.pamdas.org/static/sprite-src/fence_voltage_rep.svg | G21: 21 | H21: 3 | I21: Fence | J21: Human Activities | K21: 748f7f8a-1a22-4300-9229-b7e15e7ec142 | L21: TRUE | N21: fence_rp | O21: =HYPERLINK("#'fence_rp'!A1","Open") -> Open
A22: gunshot | B22: Gunshot Report | C22: v1 | D22: https://mugie.pamdas.org/api/v1.0/activity/events/schema/eventtype/gunshot | E22: AK_47_rep | F22: https://mugie.pamdas.org/static/sprite-src/AK_47_rep.svg | G22: 4 | H22: 0 | I22: Gunshot | J22: Human Activities | K22: 748f7f8a-1a22-4300-9229-b7e15e7ec142 | L22: TRUE | N22: gunshot | O22: =HYPERLINK("#'gunshot'!A1","Open") -> Open
A23: illegal_activity | B23: EventType Test Data | C23: v1 | D23: https://mugie.pamdas.org/api/v1.0/activity/events/schema/eventtype/illegal_activity | E23: illegal_activity_rep | F23: https://mugie.pamdas.org/static/illegal_activity-black.svg | G23: 8 | H23: 1 | I23: Illegal Activity | J23: Human Activities | K23: 748f7f8a-1a22-4300-9229-b7e15e7ec142 | L23: TRUE | N23: illegal_activity | O23: =HYPERLINK("#'illegal_activity'!A1","Open") -> Open
A24: illegal_grazing | B24: Illegal grazing Report | C24: v1 | D24: https://mugie.pamdas.org/api/v1.0/activity/events/schema/eventtype/illegal_grazing | E24: activity_rep | F24: https://mugie.pamdas.org/static/sprite-src/activity_rep.svg | G24: 7 | H24: 3 | I24: Illegal Grazing | J24: Human Activities | K24: 748f7f8a-1a22-4300-9229-b7e15e7ec142 | L24: TRUE | N24: illegal_grazing | O24: =HYPERLINK("#'illegal_grazing'!A1","Open") -> Open
A25: incident_collection | B25: Incident Collection | C25: v1 | D25: https://mugie.pamdas.org/api/v1.0/activity/events/schema/eventtype/incident_collection | E25: incident_collection | F25: https://mugie.pamdas.org/static/incident_collection-black.svg | G25: 3 | H25: 2 | I25: Incident Collection | J25: Human Activities | K25: 748f7f8a-1a22-4300-9229-b7e15e7ec142 | L25: TRUE | N25: incident_collection | O25: =HYPERLINK("#'incident_collection'!A1","Open") -> Open
A26: invasiveplantrep | B26: Alien Plant Control Report | C26: v1 | D26: https://mugie.pamdas.org/api/v1.0/activity/events/schema/eventtype/invasiveplantrep | E26: invasive_species_rep | F26: https://mugie.pamdas.org/static/invasive_species-black.svg | G26: 2 | H26: 1 | I26: Invasive Plant Control | J26: Human Activities | K26: 748f7f8a-1a22-4300-9229-b7e15e7ec142 | L26: TRUE | N26: invasiveplantrep | O26: =HYPERLINK("#'invasiveplantrep'!A1","Open") -> Open
A27: natural_production | B27: Natural production Report | C27: v1 | D27: https://mugie.pamdas.org/api/v1.0/activity/events/schema/eventtype/natural_production | E27: invasive_species_rep | F27: https://mugie.pamdas.org/static/invasive_species-black.svg | G27: 6 | H27: 3 | I27: Natural Products | J27: Human Activities | K27: 748f7f8a-1a22-4300-9229-b7e15e7ec142 | L27: TRUE | N27: natural_production | O27: =HYPERLINK("#'natural_production'!A1","Open") -> Open
A28: on_transit | B28: Livestock On transit | C28: v1 | D28: https://mugie.pamdas.org/api/v1.0/activity/events/schema/eventtype/on_transit | E28: livestock_movement_rep | F28: https://mugie.pamdas.org/static/sprite-src/livestock_movement_rep.svg | G28: 6 | H28: 1 | I28: Livestock On Transit | J28: Human Activities | K28: 748f7f8a-1a22-4300-9229-b7e15e7ec142 | L28: TRUE | N28: on_transit | O28: =HYPERLINK("#'on_transit'!A1","Open") -> Open
A29: recoveriestrophies | B29: EventType Recoveries - Trophies (confiscationtrophies_rep) | C29: v1 | D29: https://mugie.pamdas.org/api/v1.0/activity/events/schema/eventtype/recoveriestrophies | E29: recoveriestrophies | F29: https://mugie.pamdas.org/static/generic-black.svg | G29: 30 | H29: 0 | I29: Recoveries - Trophies | J29: Human Activities | K29: 748f7f8a-1a22-4300-9229-b7e15e7ec142 | L29: TRUE | N29: recoveriestrophies | O29: =HYPERLINK("#'recoveriestrophies'!A1","Open") -> Open
A30: sandalwood | B30: Placeholder schema | C30: v1 | D30: https://mugie.pamdas.org/api/v1.0/activity/events/schema/eventtype/sandalwood | E30: natural_feature_rep | F30: https://mugie.pamdas.org/static/sprite-src/natural_feature_rep.svg | G30: 2 | H30: 0 | I30: Sandalwood | J30: Human Activities | K30: 748f7f8a-1a22-4300-9229-b7e15e7ec142 | L30: TRUE | N30: sandalwood | O30: =HYPERLINK("#'sandalwood'!A1","Open") -> Open
A31: sandalwood_poly | B31: Placeholder schema | C31: v1 | D31: https://mugie.pamdas.org/api/v1.0/activity/events/schema/eventtype/sandalwood_poly | E31: natural_feature_rep | F31: https://mugie.pamdas.org/static/sprite-src/natural_feature_rep.svg | G31: 2 | H31: 0 | I31: Sandalwood Polygon | J31: Human Activities | K31: 748f7f8a-1a22-4300-9229-b7e15e7ec142 | L31: TRUE | N31: sandalwood_poly | O31: =HYPERLINK("#'sandalwood_poly'!A1","Open") -> Open
A32: snares | B32: Snares Report | C32: v1 | D32: https://mugie.pamdas.org/api/v1.0/activity/events/schema/eventtype/snares | E32: snare_rep | F32: https://mugie.pamdas.org/static/snare-black.svg | G32: 7 | H32: 3 | I32: Snares | J32: Human Activities | K32: 748f7f8a-1a22-4300-9229-b7e15e7ec142 | L32: TRUE | N32: snares | O32: =HYPERLINK("#'snares'!A1","Open") -> Open
A33: spoor | B33: Human Spoor | C33: v1 | D33: https://mugie.pamdas.org/api/v1.0/activity/events/schema/eventtype/spoor | E33: spoor_rep | F33: https://mugie.pamdas.org/static/spoor-black.svg | G33: 4 | H33: 4 | I33: Spoor | J33: Human Activities | K33: 748f7f8a-1a22-4300-9229-b7e15e7ec142 | L33: TRUE | N33: spoor | O33: =HYPERLINK("#'spoor'!A1","Open") -> Open
A34: trespassing | B34: Trespassing Report | C34: v1 | D34: https://mugie.pamdas.org/api/v1.0/activity/events/schema/eventtype/trespassing | E34: crossing_rep | F34: https://mugie.pamdas.org/static/sprite-src/crossing_rep.svg | G34: 5 | H34: 2 | I34: Trespassing | J34: Human Activities | K34: 748f7f8a-1a22-4300-9229-b7e15e7ec142 | L34: TRUE | N34: trespassing | O34: =HYPERLINK("#'trespassing'!A1","Open") -> Open
A35: wood_collecting | B35: Wood collecting Report | C35: v1 | D35: https://mugie.pamdas.org/api/v1.0/activity/events/schema/eventtype/wood_collecting | E35: timber-observation_rep | F35: https://mugie.pamdas.org/static/sprite-src/timber-observation_rep.svg | G35: 9 | H35: 4 | I35: Wood Collection | J35: Human Activities | K35: 748f7f8a-1a22-4300-9229-b7e15e7ec142 | L35: TRUE | N35: wood_collecting | O35: =HYPERLINK("#'wood_collecting'!A1","Open") -> Open
A36: baton_rep | B36: EventType Test Data | C36: v1 | D36: https://mugie.pamdas.org/api/v1.0/activity/events/schema/eventtype/baton_rep | E36: ranger_shot_rep | F36: https://mugie.pamdas.org/static/ranger_shot_rep-black.svg | G36: 10 | H36: 1 | I36: Baton Report | J36: Human Wildlife Conflict | K36: e28e5162-3409-48ce-8d01-8bade1d5b4d6 | L36: TRUE | N36: baton_rep | O36: =HYPERLINK("#'baton_rep'!A1","Open") -> Open
A37: hwc_crops | B37: EventType Test Data | C37: v1 | D37: https://mugie.pamdas.org/api/v1.0/activity/events/schema/eventtype/hwc_crops | E37: human_wildlife_conflict_rep | F37: https://mugie.pamdas.org/static/human_wildlife_conflict-black.svg | G37: 24 | H37: 1 | I37: HWC Crop Damage | J37: Human Wildlife Conflict | K37: e28e5162-3409-48ce-8d01-8bade1d5b4d6 | L37: TRUE | N37: hwc_crops | O37: =HYPERLINK("#'hwc_crops'!A1","Open") -> Open
A38: hwc_human_death | B38: EventType Test Data | C38: v1 | D38: https://mugie.pamdas.org/api/v1.0/activity/events/schema/eventtype/hwc_human_death | E38: hwc_human_death_rep | F38: https://mugie.pamdas.org/static/sprite-src/hwc_human_death_rep.svg | G38: 20 | H38: 1 | I38: HWC Human Death | J38: Human Wildlife Conflict | K38: e28e5162-3409-48ce-8d01-8bade1d5b4d6 | L38: TRUE | N38: hwc_human_death | O38: =HYPERLINK("#'hwc_human_death'!A1","Open") -> Open
A39: hwc_human_injury | B39: EventType Test Data | C39: v1 | D39: https://mugie.pamdas.org/api/v1.0/activity/events/schema/eventtype/hwc_human_injury | E39: hwc_alert_rep | F39: https://mugie.pamdas.org/static/sprite-src/hwc_alert_rep.svg | G39: 20 | H39: 1 | I39: HWC Human Injury | J39: Human Wildlife Conflict | K39: e28e5162-3409-48ce-8d01-8bade1d5b4d6 | L39: TRUE | N39: hwc_human_injury | O39: =HYPERLINK("#'hwc_human_injury'!A1","Open") -> Open
A40: hwc_livestock_pred_rv00 | B40: EventType Test Data | C40: v1 | D40: https://mugie.pamdas.org/api/v1.0/activity/events/schema/eventtype/hwc_livestock_pred_rv00 | E40: livestock-death_rep | F40: https://mugie.pamdas.org/static/sprite-src/livestock-death_rep.svg | G40: 22 | H40: 4 | I40: HWC Livestock Predation | J40: Human Wildlife Conflict | K40: e28e5162-3409-48ce-8d01-8bade1d5b4d6 | L40: TRUE | N40: hwc_livestock_pred_rv00 | O40: =HYPERLINK("#'hwc_livestock_pred_rv00'!A1","Open") -> Open
...

Sheet suyian_schemas
A1: event_value | B1: schema_title | C1: api_version | D1: schema_id | E1: icon_id | F1: image_url | G1: n_fields | H1: n_enums | I1: event_name | J1: event_category_display | K1: event_category_id | L1: event_is_active | M1: event_updated_at | N1: sheet_name
A2: acoustic_detection | B2: Acoustic Detection (acoustic_detection) | C2: v1 | D2: https://suyian.pamdas.org/api/v1.0/activity/events/schema/eventtype/acoustic_detection | E2: radar_rep | F2: https://suyian.pamdas.org/static/sprite-src/radar_rep.svg | G2: 3 | H2: 0 | I2: Acoustic Detection | J2: Analyzer Event | K2: ef230385-5afc-40d1-ad07-c811f6da2b3c | L2: TRUE | N2: acoustic_detection
A3: baboon_rep | B3: Total Number of Animals Sighted | C3: v1 | D3: https://suyian.pamdas.org/api/v1.0/activity/events/schema/eventtype/baboon_rep | E3: baboon_rep | F3: https://suyian.pamdas.org/static/sprite-src/baboon_rep.svg | G3: 1 | H3: 0 | I3: Baboon | J3: Wildlife Monitoring. | K3: 7113fef7-7eaf-460d-82e0-1462171bcd57 | L3: TRUE | N3: baboon_rep
A4: blackbackedjackal | B4: Total Number of Animals Sighted | C4: v1 | D4: https://suyian.pamdas.org/api/v1.0/activity/events/schema/eventtype/blackbackedjackal | E4: jackal_rep | F4: https://suyian.pamdas.org/static/sprite-src/jackal_rep.svg | G4: 1 | H4: 0 | I4: Black-backed jackal | J4: Wildlife Monitoring. | K4: 7113fef7-7eaf-460d-82e0-1462171bcd57 | L4: TRUE | N4: blackbackedjackal
A5: buffalo_rep | B5: Total Number of Animals Sighted | C5: v1 | D5: https://suyian.pamdas.org/api/v1.0/activity/events/schema/eventtype/buffalo_rep | E5: buffalo_rep | F5: https://suyian.pamdas.org/static/sprite-src/buffalo_rep.svg | G5: 1 | H5: 0 | I5: Buffalo | J5: Wildlife Monitoring. | K5: 7113fef7-7eaf-460d-82e0-1462171bcd57 | L5: TRUE | N5: buffalo_rep
A6: cheetah_rep | B6: Total Number of Animals Sighted | C6: v1 | D6: https://suyian.pamdas.org/api/v1.0/activity/events/schema/eventtype/cheetah_rep | E6: cheetah_sighting_rep | F6: https://suyian.pamdas.org/static/sprite-src/cheetah_sighting_rep.svg | G6: 1 | H6: 0 | I6: Cheetah | J6: Wildlife Monitoring. | K6: 7113fef7-7eaf-460d-82e0-1462171bcd57 | L6: TRUE | N6: cheetah_rep
A7: dead_animal_revision_2 | B7: EventType Test Data | C7: v1 | D7: https://suyian.pamdas.org/api/v1.0/activity/events/schema/eventtype/dead_animal_revision_2 | E7: carcass_rep | F7: https://suyian.pamdas.org/static/carcass-black.svg | G7: 25 | H7: 12 | I7: Dead Animal | J7: VETERINARY | K7: 72142042-edc8-4770-b6a7-021cee90169a | L7: TRUE | N7: dead_animal_revision_2
A8: dikdik_rep | B8: Total Number of Animals Sighted | C8: v1 | D8: https://suyian.pamdas.org/api/v1.0/activity/events/schema/eventtype/dikdik_rep | E8: duiker_rep | F8: https://suyian.pamdas.org/static/sprite-src/duiker_rep.svg | G8: 1 | H8: 0 | I8: Dikdik | J8: Wildlife Monitoring. | K8: 7113fef7-7eaf-460d-82e0-1462171bcd57 | L8: TRUE | N8: dikdik_rep
A9: distancesampling_rep | B9: Distance Sampling Report | C9: v1 | D9: https://suyian.pamdas.org/api/v1.0/activity/events/schema/eventtype/distancesampling_rep | E9: sighting_rep | F9: https://suyian.pamdas.org/static/sprite-src/sighting_rep.svg | G9: 5 | H9: 2 | I9: Distance Sampling | J9: Wildlife Monitoring. | K9: 7113fef7-7eaf-460d-82e0-1462171bcd57 | L9: TRUE | N9: distancesampling_rep
A10: eland_rep | B10: Total Number of Animals Sighted | C10: v1 | D10: https://suyian.pamdas.org/api/v1.0/activity/events/schema/eventtype/eland_rep | E10: eland_rep | F10: https://suyian.pamdas.org/static/sprite-src/eland_rep.svg | G10: 1 | H10: 0 | I10: Eland | J10: Wildlife Monitoring. | K10: 7113fef7-7eaf-460d-82e0-1462171bcd57 | L10: TRUE | N10: eland_rep
A11: elephant_mortality_mike | B11: Elephant Mortality | C11: v1 | D11: https://suyian.pamdas.org/api/v1.0/activity/events/schema/eventtype/elephant_mortality_mike | E11: elephant_mortality_rep | F11: https://suyian.pamdas.org/static/elephant_mortality-black.svg | G11: 9 | H11: 7 | I11: Elephant Mortality | J11: Wildlife Monitoring. | K11: 7113fef7-7eaf-460d-82e0-1462171bcd57 | L11: TRUE | N11: elephant_mortality_mike
A12: elephant_rep | B12: Total Number of Animals Sighted | C12: v1 | D12: https://suyian.pamdas.org/api/v1.0/activity/events/schema/eventtype/elephant_rep | E12: elephant_signs-event | F12: https://suyian.pamdas.org/static/sprite-src/elephant_signs-event.svg | G12: 1 | H12: 0 | I12: Elephant | J12: Wildlife Monitoring. | K12: 7113fef7-7eaf-460d-82e0-1462171bcd57 | L12: TRUE | N12: elephant_rep
A13: firms_rep | B13: FIRMS Fire Report Schema | C13: v1 | D13: https://suyian.pamdas.org/api/v1.0/activity/events/schema/eventtype/firms_rep | E13: firms_rep | F13: https://suyian.pamdas.org/static/firms_rep-black.svg | G13: 6 | H13: 0 | I13: FIRMS Report | J13: Analyzer Event | K13: ef230385-5afc-40d1-ad07-c811f6da2b3c | L13: TRUE | N13: firms_rep
... A55: wilddog_rep | B55: Total Number of Animals Sighted | C55: v1 | D55: https://suyian.pamdas.org/api/v1.0/activity/events/schema/eventtype/wilddog_rep | E55: wild_dog_rep | F55: https://suyian.pamdas.org/static/sprite-src/wild_dog_rep.svg | G55: 1 | H55: 0 | I55: Wild dog | J55: Wildlife Monitoring. | K55: 7113fef7-7eaf-460d-82e0-1462171bcd57 | L55: TRUE | N55: wilddog_rep

Sheet sosian_schemas
A1: event_value | B1: schema_title | C1: api_version | D1: schema_id | E1: icon_id | F1: image_url | G1: n_fields | H1: n_enums | I1: event_name | J1: event_category_display | K1: event_category_id | L1: event_is_active | M1: event_updated_at | N1: sheet_name
A2: acoustic_detection | B2: Acoustic Detection (acoustic_detection) | C2: v1 | D2: https://sosian.pamdas.org/api/v1.0/activity/events/schema/eventtype/acoustic_detection | E2: radar_rep | F2: https://sosian.pamdas.org/static/sprite-src/radar_rep.svg | G2: 3 | H2: 0 | I2: Acoustic Detection | J2: Analyzer Event | K2: ef230385-5afc-40d1-ad07-c811f6da2b3c | L2: TRUE | N2: acoustic_detection
A3: area_polygon_tool | B3: Polygon Tool (polygon_sighting) | C3: v1 | D3: https://sosian.pamdas.org/api/v1.0/activity/events/schema/eventtype/area_polygon_tool | E3: geofence_break_rep | F3: https://sosian.pamdas.org/static/geofence_break-black.svg | G3: 3 | H3: 2 | I3: Area Measurement Tool | J3: Habitat Health | K3: a869348d-b8a8-426c-a938-c4627de48216 | L3: TRUE | N3: area_polygon_tool
A4: buffalo | B4: Buffalo Report | C4: v1 | D4: https://sosian.pamdas.org/api/v1.0/activity/events/schema/eventtype/buffalo | E4: buffalo_rep | F4: https://sosian.pamdas.org/static/sprite-src/buffalo_rep.svg | G4: 1 | H4: 0 | I4: Buffalo | J4: Wildlife Sighting | K4: e7860c5e-49f2-4393-b733-afba3e8b51eb | L4: TRUE | N4: buffalo
A5: bushmeattrading | B5: Bushmeat & Trading Report | C5: v1 | D5: https://sosian.pamdas.org/api/v1.0/activity/events/schema/eventtype/bushmeattrading | E5: bushmeat_poacher_rep | F5: https://sosian.pamdas.org/static/sprite-src/bushmeat_poacher_rep.svg | G5: 8 | H5: 3 | I5: Bushmeat & Trophy | J5: Human Activities | K5: 116904c3-87e9-4599-bf1f-530109c13cb7 | L5: TRUE | N5: bushmeattrading
A6: carcasses | B6: Carcasses Report | C6: v1 | D6: https://sosian.pamdas.org/api/v1.0/activity/events/schema/eventtype/carcasses | E6: carcass_rep | F6: https://sosian.pamdas.org/static/carcass-black.svg | G6: 8 | H6: 4 | I6: Carcasses | J6: Wildlife Sighting | K6: e7860c5e-49f2-4393-b733-afba3e8b51eb | L6: TRUE | N6: carcasses
A7: cheetah | B7: cheetah Report | C7: v1 | D7: https://sosian.pamdas.org/api/v1.0/activity/events/schema/eventtype/cheetah | E7: cheetah_sighting_rep | F7: https://sosian.pamdas.org/static/sprite-src/cheetah_sighting_rep.svg | G7: 1 | H7: 0 | I7: Cheetah | J7: Wildlife Sighting | K7: e7860c5e-49f2-4393-b733-afba3e8b51eb | L7: TRUE | N7: cheetah
A8: crop_damage | B8: Crop Damage Report | C8: v1 | D8: https://sosian.pamdas.org/api/v1.0/activity/events/schema/eventtype/crop_damage | E8: land_clearance_rep | F8: https://sosian.pamdas.org/static/sprite-src/land_clearance_rep.svg | G8: 10 | H8: 6 | I8: Crop Damage | J8: Human Wildlife Interaction | K8: d78ae70e-0aae-425b-9ca1-5b96a663f4c8 | L8: TRUE | N8: crop_damage
A9: cropdamage_polygon_tool | B9: Crop Damage polygon Report | C9: v1 | D9: https://sosian.pamdas.org/api/v1.0/activity/events/schema/eventtype/cropdamage_polygon_tool | E9: geofence_break_rep | F9: https://sosian.pamdas.org/static/geofence_break-black.svg | G9: 10 | H9: 6 | I9: Crop Damage (Polygon Tool) | J9: Human Wildlife Interaction | K9: d78ae70e-0aae-425b-9ca1-5b96a663f4c8 | L9: TRUE | N9: cropdamage_polygon_tool
A10: dead_animal | B10: EventType Test Data | C10: v1 | D10: https://sosian.pamdas.org/api/v1.0/activity/events/schema/eventtype/dead_animal | E10: wildlife_mortality_rep | F10: https://sosian.pamdas.org/static/sprite-src/wildlife_mortality_rep.svg | G10: 25 | H10: 12 | I10: Dead Animal | J10: VETERINARY | K10: 731d3546-eaf5-46c9-bbff-df0c948d8396 | L10: TRUE | N10: dead_animal
A11: eland | B11: Eland Report | C11: v1 | D11: https://sosian.pamdas.org/api/v1.0/activity/events/schema/eventtype/eland | E11: eland_rep | F11: https://sosian.pamdas.org/static/sprite-src/eland_rep.svg | G11: 1 | H11: 0 | I11: Eland | J11: Wildlife Sighting | K11: e7860c5e-49f2-4393-b733-afba3e8b51eb | L11: TRUE | N11: eland
A12: elephant_sighting | B12: Elephant Report | C12: v1 | D12: https://sosian.pamdas.org/api/v1.0/activity/events/schema/eventtype/elephant_sighting | E12: elephant_sighting_rep | F12: https://sosian.pamdas.org/static/elephant_sighting-black.svg | G12: 1 | H12: 0 | I12: Elephant | J12: Wildlife Sighting | K12: e7860c5e-49f2-4393-b733-afba3e8b51eb | L12: TRUE | N12: elephant_sighting
A13: fence_damage | B13: Fence damage Report | C13: v1 | D13: https://sosian.pamdas.org/api/v1.0/activity/events/schema/eventtype/fence_damage | E13: fence_breakage_rep | F13: https://sosian.pamdas.org/static/fence_breakage-black.svg | G13: 8 | H13: 3 | I13: Fence Damage | J13: Human Activities | K13: 116904c3-87e9-4599-bf1f-530109c13cb7 | L13: TRUE | N13: fence_damage
... A60: wood_collecting | B60: Wood collecting Report | C60: v1 | D60: https://sosian.pamdas.org/api/v1.0/activity/events/schema/eventtype/wood_collecting | E60: timber-observation_rep | F60: https://sosian.pamdas.org/static/sprite-src/timber-observation_rep.svg | G60: 9 | H60: 5 | I60: Wood Collection | J60: Human Activities | K60: 116904c3-87e9-4599-bf1f-530109c13cb7 | L60: TRUE | N60: wood_collecting

Sheet aip_polygon
A1: event_value | B1: event_name | C1: event_category_display | D1: event_category_id | E1: path | F1: json_key | G1: ui_title | H1: type | I1: format | J1: required | K1: is_array | L1: array_item_type | M1: enum_values | N1: enum_names | O1: inactive_enum | P1: enum_images | Q1: minimum | R1: maximum | S1: pattern | T1: default | U1: examples | V1: description | W1: key_ref | X1: notes
A2: aip_polygon | B2: Alien Invasive Plants Polygon | C2: Bio And Eco Monitoring | D2: 03cc816c-724a-4365-8eb7-3a09843ff196 | E2: invasivealienplants_alienplantspecies | F2: invasivealienplants_alienplantspecies | G2: Alien Plant Species | H2: string | J2: FALSE | K2: FALSE | M2: acaciamearnsiiblackwattle acaciamelanoxylonaustralianblackwood austrocylindropuntiasubalatadevilsrope bryophyllumdelagoensemotherofmillions bryophyllumfedtschenkoistonecrop catharanthusroseusrosyperiwinkle cereusjamaceruqueenofthenight chromoleanaodoratatriffidweed cuscutareflexagoldendodder daturastramoniumcommonthornapple eucalyptussppgumtrees euryopschrysanthemoidesgoldendaisy grevilliarobustasilkyoak kalanchoebeharensisvelvetelephantear lantanacamaraverbena opuntiaficusindicafigopuntia opuntiastrictapricklypear partheniumhysterophorusfamineweed solanummauritianumbugweed tithoniadiversifoliamexicansunflower agave_sisal argemone_poppy cirsium_thistle senna_arsenicbush xanthium_cocklebur | N2: {"acaciamearnsiiblackwattle":"Acacia Mearnsii - Black Wattle","acaciamelanoxylonaustralianblackwood":"Acacia Melanoxylon - Australian Blackwood","agave_sisal":"Agave sisalana - Sisal hemp","argemone_poppy":"Argemone mexicana - Mexican poppy","austrocylindropuntiasubalatadevilsrope":"Austrocylindropuntia Subalata - Devils Rope","bryophyllumdelagoensemotherofmillions":"Bryophyllum Delagoense - Mother of Millions","bryophyllumfedtschenkoistonecrop":"Bryophyllum Fedtschenkoi - Stonecrop","catharanthusroseusrosyperiwinkle":"Catharanthus Roseus - Rosy Periwinkle","cereusjamaceruqueenofthenight":"Cereus Jamaceru - Queen of the Night","chromoleanaodoratatriffidweed":"Chromoleana Odorata - Triffid Weed","cirsium_thistle":"Cirsium vulgare - Common thistle","cuscutareflexagoldendodder":"Cuscuta Reflexa - Golden Dodder","daturastramoniumcommonthornapple":"Datura Stramonium - Common Thorn Apple","eucalyptussppgumtrees":"Eucalyptus Spp. - Gum Trees","euryopschrysanthemoidesgoldendaisy":"Euryops Chrysanthemoides - Golden Daisy","grevilliarobustasilkyoak":"Grevillia Robusta - Silky Oak","kalanchoebeharensisvelvetelephantear":"Kalanchoe Beharensis - Velvet Elephant Ear","lantanacamaraverbena":"Lantana Camara - Verbena","opuntiaficusindicafigopuntia":"Opuntia Ficus Indica - Fig Opuntia","opuntiastrictapricklypear":"Opuntia Stricta - Prickly Pear","partheniumhysterophorusfamineweed":"Parthenium Hysterophorus - Famine Weed","senna_arsenicbush":"Senna occidentalis - Arsenic bush","solanummauritianumbugweed":"Solanum Mauritianum - Bug Weed","tithoniadiversifoliamexicansunflower":"Tithonia Diversifolia - Mexican Sunflower","xanthium_cocklebur":"Xanthium strumarium - Cocklebur"} | P2: {"acaciamearnsiiblackwattle":"string","acaciamelanoxylonaustralianblackwood":"string","austrocylindropuntiasubalatadevilsrope":"string","bryophyllumdelagoensemotherofmillions":"string","bryophyllumfedtschenkoistonecrop":"string","catharanthusroseusrosyperiwinkle":"string","cereusjamaceruqueenofthenight":"string","chromoleanaodoratatriffidweed":"string","cuscutareflexagoldendodder":"string","daturastramoniumcommonthornapple":"string","eucalyptussppgumtrees":"string","euryopschrysanthemoidesgoldendaisy":"string","grevilliarobustasilkyoak":"string","kalanchoebeharensisvelvetelephantear":"string","lantanacamaraverbena":"string","opuntiaficusindicafigopuntia":"string","opuntiastrictapricklypear":"string","partheniumhysterophorusfamineweed":"string","solanummauritianumbugweed":"string","tithoniadiversifoliamexicansunflower":"string"}
A3: aip_polygon | B3: Alien Invasive Plants Polygon | C3: Bio And Eco Monitoring | D3: 03cc816c-724a-4365-8eb7-3a09843ff196 | E3: invasivealienplants_phenologicalstate | F3: invasivealienplants_phenologicalstate | J3: FALSE | K3: FALSE | W3: invasivealienplants_phenologicalstate
A4: aip_polygon | B4: Alien Invasive Plants Polygon | C4: Bio And Eco Monitoring | D4: 03cc816c-724a-4365-8eb7-3a09843ff196 | E4: invasivealienplants_iapdensity | F4: invasivealienplants_iapdensity | G4: IAP Density | H4: string | J4: FALSE | K4: FALSE | M4: 1 2 3 4 5 | N4: {"1":"1","2":"2","3":"3","4":"4","5":"5"} | P4: {"1":"string","2":"string","3":"string","4":"string","5":"string"}
A5: aip_polygon | B5: Alien Invasive Plants Polygon | C5: Bio And Eco Monitoring | D5: 03cc816c-724a-4365-8eb7-3a09843ff196 | E5: invasivealienplants_biocontroldensity | F5: invasivealienplants_biocontroldensity | G5: Bio-control Density | H5: string | J5: FALSE | K5: FALSE | M5: 0 1 2 3 | N5: {"0":"0","1":"1","2":"2","3":"3"} | P5: {"0":"string","1":"string","2":"string","3":"string"}
A6: aip_polygon | B6: Alien Invasive Plants Polygon | C6: Bio And Eco Monitoring | D6: 03cc816c-724a-4365-8eb7-3a09843ff196 | E6: invasivealienplants_controlregimedetails | F6: invasivealienplants_controlregimedetails | G6: Control Regime Details | H6: string | J6: FALSE | K6: FALSE | M6: primarytreatment firstyearfollowup secondyearfollowup thirdyearfollowup | N6: {"firstyearfollowup":"First Year Follow-up","primarytreatment":"Primary Treatment","secondyearfollowup":"Second Year Follow-up","thirdyearfollowup":"Third Year Follow-up"} | P6: {"firstyearfollowup":"string","primarytreatment":"string","secondyearfollowup":"string","thirdyearfollowup":"string"}
A7: aip_polygon | B7: Alien Invasive Plants Polygon | C7: Bio And Eco Monitoring | D7: 03cc816c-724a-4365-8eb7-3a09843ff196 | E7: invasivealienplants_controlmethod | F7: invasivealienplants_controlmethod | G7: Control Method | H7: string | J7: FALSE | K7: FALSE | M7: biological chemical mechanical burning | N7: {"biological":"Biological","burning":"Burning","chemical":"Chemical","mechanical":"Mechanical"} | P7: {"biological":"string","burning":"string","chemical":"string","mechanical":"string"}
A8: aip_polygon | B8: Alien Invasive Plants Polygon | C8: Bio And Eco Monitoring | D8: 03cc816c-724a-4365-8eb7-3a09843ff196 | E8: invasivealienplants_controlapplication | F8: invasivealienplants_controlapplication | G8: Control Application | H8: string | J8: FALSE | K8: FALSE | M8: bioagentrelease cutstumptreatment foliarspray frilling ringbarking uprooting | N8: {"bioagentrelease":"Bio-agent Release","cutstumptreatment":"Cut Stump Treatment","foliarspray":"Foliar Spray","frilling":"Frilling","ringbarking":"Ring Barking","uprooting":"Up-Rooting"} | P8: {"bioagentrelease":"string","cutstumptreatment":"string","foliarspray":"string","frilling":"string","ringbarking":"string","uprooting":"string"}
A9: aip_polygon | B9: Alien Invasive Plants Polygon | C9: Bio And Eco Monitoring | D9: 03cc816c-724a-4365-8eb7-3a09843ff196 | E9: invasivealienplants_herbicideused | F9: invasivealienplants_herbicideused | G9: Herbicide Used | H9: string | J9: FALSE | K9: FALSE
A10: aip_polygon | B10: Alien Invasive Plants Polygon | C10: Bio And Eco Monitoring | D10: 03cc816c-724a-4365-8eb7-3a09843ff196 | E10: invasivealienplants_herbicideconcentration | F10: invasivealienplants_herbicideconcentration | G10: Herbicide Concentration % | H10: number | J10: FALSE | K10: FALSE | Q10: 0
A11: aip_polygon | B11: Alien Invasive Plants Polygon | C11: Bio And Eco Monitoring | D11: 03cc816c-724a-4365-8eb7-3a09843ff196 | E11: invasivealienplants_biologicalcontrolapplied | F11: invasivealienplants_biologicalcontrolapplied | G11: Biological Control Applied | H11: string | J11: FALSE | K11: FALSE | M11: cochineal none | N11: {"cochineal":"Cochineal","none":"None"}
A12: aip_polygon | B12: Alien Invasive Plants Polygon | C12: Bio And Eco Monitoring | D12: 03cc816c-724a-4365-8eb7-3a09843ff196 | E12: invasivealienplants_distributionaream | F12: invasivealienplants_distributionaream | G12: Distribution Area (m) | H12: number | J12: FALSE | K12: FALSE | Q12: 0
A13: aip_polygon | B13: Alien Invasive Plants Polygon | C13: Bio And Eco Monitoring | D13: 03cc816c-724a-4365-8eb7-3a09843ff196 | E13: invasivealienplants_weatherconditions | F13: invasivealienplants_weatherconditions | J13: FALSE | K13: FALSE | W13: invasivealienplants_weatherconditions
A14: aip_polygon | B14: Alien Invasive Plants Polygon | C14: Bio And Eco Monitoring | D14: 03cc816c-724a-4365-8eb7-3a09843ff196 | E14: invasivealienplants_watchkeepervalidation | F14: invasivealienplants_watchkeepervalidation | G14: Watch Keeper Validation | H14: string | J14: FALSE | K14: FALSE
A15: aip_polygon | B15: Alien Invasive Plants Polygon | C15: Bio And Eco Monitoring | D15: 03cc816c-724a-4365-8eb7-3a09843ff196 | E15: invasivealienplants_actionschecklist | F15: invasivealienplants_actionschecklist | J15: FALSE | K15: FALSE | W15: invasivealienplants_actionschecklist
A16: aip_polygon | B16: Alien Invasive Plants Polygon | C16: Bio And Eco Monitoring | D16: 03cc816c-724a-4365-8eb7-3a09843ff196 | E16: invasivealienplants_commandervalidation | F16: invasivealienplants_commandervalidation | G16: Commander Validation | H16: string | J16: FALSE | K16: FALSE
A17: aip_polygon | B17: Alien Invasive Plants Polygon | C17: Bio And Eco Monitoring | D17: 03cc816c-724a-4365-8eb7-3a09843ff196 | E17: invasivealienplants_treatmentefficacyatonemonth | F17: invasivealienplants_treatmentefficacyatonemonth | G17: Treatment Efficacy at One Month (%) | H17: number | J17: FALSE | K17: FALSE | Q17: 0
A18: aip_polygon | B18: Alien Invasive Plants Polygon | C18: Bio And Eco Monitoring | D18: 03cc816c-724a-4365-8eb7-3a09843ff196 | E18: invasivealienplants_conclusion | F18: invasivealienplants_conclusion | G18: Conclusion | H18: string | J18: FALSE | K18: FALSE

Sheet aip_tourism
A1: event_value | B1: event_name | C1: event_category_display | D1: event_category_id | E1: path | F1: json_key | G1: ui_title | H1: type | I1: format | J1: required | K1: is_array | L1: array_item_type | M1: enum_values | N1: enum_names | O1: inactive_enum | P1: enum_images | Q1: minimum | R1: maximum | S1: pattern | T1: default | U1: examples | V1: description | W1: key_ref | X1: notes
